2025-09-09 21:49:00,677-ERROR-An error occured
Traceback (most recent call last):
  File "C:\Users\ASUS\AppData\Local\Temp\ipykernel_6336\1944028996.py", line 23, in log_exception
    x = 1/0
        ~^~
ZeroDivisionError: division by zero
2025-09-09 21:55:09,892-ERROR-An error occured
Traceback (most recent call last):
  File "C:\Users\ASUS\AppData\Local\Temp\ipykernel_13268\1896195708.py", line 23, in log_exception
    x = 1/0
        ~^~
ZeroDivisionError: division by zero
2025-09-09 21:55:40,532-ERROR-An error occured
Traceback (most recent call last):
  File "C:\Users\ASUS\AppData\Local\Temp\ipykernel_12480\1896195708.py", line 23, in log_exception
    x = 1/0
        ~^~
ZeroDivisionError: division by zero
